INFO:snowflake.connector.connection:closed
INFO:snowflake.connector.connection:No async queries seem to be running, deleting session
WARNING:snowflake.connector.vendored.urllib3.connectionpool:Retrying (Retry(total=0, connect=None, read=None, redirect=None, status=None)) after connection broken by 'NewConnectionError('<snowflake.connector.vendored.urllib3.connection.HTTPSConnection object at 0x7fc90e8eb400>: Failed to establish a new connection: [Errno -3] Temporary failure in name resolution')': /session?delete=true&request_guid=986d5a66-8f1e-4612-aac5-fd73d3f83fd7
ERROR:snowflake.connector.network:HTTPSConnectionPool(host='pra18133.us-east-1.snowflakecomputing.com', port=443): Max retries exceeded with url: /session?delete=true&request_guid=986d5a66-8f1e-4612-aac5-fd73d3f83fd7 (Caused by NewConnectionError('<snowflake.connector.vendored.urllib3.connection.HTTPSConnection object at 0x7fc90fbbfcd0>: Failed to establish a new connection: [Errno -3] Temporary failure in name resolution'))
Traceback (most recent call last):
  File "/home/josh/.local/lib/python3.10/site-packages/snowflake/connector/vendored/urllib3/connection.py", line 174, in _new_conn
    conn = connection.create_connection(
  File "/home/josh/.local/lib/python3.10/site-packages/snowflake/connector/vendored/urllib3/util/connection.py", line 72, in create_connection
    for res in socket.getaddrinfo(host, port, family, socket.SOCK_STREAM):
  File "/usr/lib/python3.10/socket.py", line 955, in getaddrinfo
    for res in _socket.getaddrinfo(host, port, family, type, proto, flags):
socket.gaierror: [Errno -3] Temporary failure in name resolution

During handling of the above exception, another exception occurred:

Traceback (most recent call last):
  File "/home/josh/.local/lib/python3.10/site-packages/snowflake/connector/vendored/urllib3/connectionpool.py", line 703, in urlopen
    httplib_response = self._make_request(
  File "/home/josh/.local/lib/python3.10/site-packages/snowflake/connector/vendored/urllib3/connectionpool.py", line 386, in _make_request
    self._validate_conn(conn)
  File "/home/josh/.local/lib/python3.10/site-packages/snowflake/connector/vendored/urllib3/connectionpool.py", line 1042, in _validate_conn
    conn.connect()
  File "/home/josh/.local/lib/python3.10/site-packages/snowflake/connector/vendored/urllib3/connection.py", line 358, in connect
    self.sock = conn = self._new_conn()
  File "/home/josh/.local/lib/python3.10/site-packages/snowflake/connector/vendored/urllib3/connection.py", line 186, in _new_conn
    raise NewConnectionError(
snowflake.connector.vendored.urllib3.exceptions.NewConnectionError: <snowflake.connector.vendored.urllib3.connection.HTTPSConnection object at 0x7fc90fbbfcd0>: Failed to establish a new connection: [Errno -3] Temporary failure in name resolution

During handling of the above exception, another exception occurred:

Traceback (most recent call last):
  File "/home/josh/.local/lib/python3.10/site-packages/snowflake/connector/vendored/requests/adapters.py", line 489, in send
    resp = conn.urlopen(
  File "/home/josh/.local/lib/python3.10/site-packages/snowflake/connector/vendored/urllib3/connectionpool.py", line 815, in urlopen
    return self.urlopen(
  File "/home/josh/.local/lib/python3.10/site-packages/snowflake/connector/vendored/urllib3/connectionpool.py", line 787, in urlopen
    retries = retries.increment(
  File "/home/josh/.local/lib/python3.10/site-packages/snowflake/connector/vendored/urllib3/util/retry.py", line 592, in increment
    raise MaxRetryError(_pool, url, error or ResponseError(cause))
snowflake.connector.vendored.urllib3.exceptions.MaxRetryError: HTTPSConnectionPool(host='pra18133.us-east-1.snowflakecomputing.com', port=443): Max retries exceeded with url: /session?delete=true&request_guid=986d5a66-8f1e-4612-aac5-fd73d3f83fd7 (Caused by NewConnectionError('<snowflake.connector.vendored.urllib3.connection.HTTPSConnection object at 0x7fc90fbbfcd0>: Failed to establish a new connection: [Errno -3] Temporary failure in name resolution'))

During handling of the above exception, another exception occurred:

Traceback (most recent call last):
  File "/home/josh/.local/lib/python3.10/site-packages/snowflake/connector/network.py", line 1018, in _request_exec
    raw_ret = session.request(
  File "/home/josh/.local/lib/python3.10/site-packages/snowflake/connector/vendored/requests/sessions.py", line 587, in request
    resp = self.send(prep, **send_kwargs)
  File "/home/josh/.local/lib/python3.10/site-packages/snowflake/connector/vendored/requests/sessions.py", line 701, in send
    r = adapter.send(request, **kwargs)
  File "/home/josh/.local/lib/python3.10/site-packages/snowflake/connector/vendored/requests/adapters.py", line 565, in send
    raise ConnectionError(e, request=request)
snowflake.connector.vendored.requests.exceptions.ConnectionError: HTTPSConnectionPool(host='pra18133.us-east-1.snowflakecomputing.com', port=443): Max retries exceeded with url: /session?delete=true&request_guid=986d5a66-8f1e-4612-aac5-fd73d3f83fd7 (Caused by NewConnectionError('<snowflake.connector.vendored.urllib3.connection.HTTPSConnection object at 0x7fc90fbbfcd0>: Failed to establish a new connection: [Errno -3] Temporary failure in name resolution'))

During handling of the above exception, another exception occurred:

Traceback (most recent call last):
  File "/home/josh/.local/lib/python3.10/site-packages/snowflake/connector/network.py", line 837, in _request_exec_wrapper
    return_object = self._request_exec(
  File "/home/josh/.local/lib/python3.10/site-packages/snowflake/connector/network.py", line 1105, in _request_exec
    raise RetryRequest(err)
snowflake.connector.network.RetryRequest: HTTPSConnectionPool(host='pra18133.us-east-1.snowflakecomputing.com', port=443): Max retries exceeded with url: /session?delete=true&request_guid=986d5a66-8f1e-4612-aac5-fd73d3f83fd7 (Caused by NewConnectionError('<snowflake.connector.vendored.urllib3.connection.HTTPSConnection object at 0x7fc90fbbfcd0>: Failed to establish a new connection: [Errno -3] Temporary failure in name resolution'))
